2024-06-03 12:06:00,656 INFO    StreamThr :44203 [internal.py:wandb_internal():85] W&B internal server running at pid: 44203, started at: 2024-06-03 12:06:00.652875
2024-06-03 12:06:00,658 DEBUG   HandlerThread:44203 [handler.py:handle_request():158] handle_request: status
2024-06-03 12:06:00,673 INFO    WriterThread:44203 [datastore.py:open_for_write():87] open: /Users/rishubbhatia/Documents/master thesis/Master-Thesis-GNN/wandb/run-20240603_120600-1kln2gg8/run-1kln2gg8.wandb
2024-06-03 12:06:00,674 DEBUG   SenderThread:44203 [sender.py:send():378] send: header
2024-06-03 12:06:00,738 DEBUG   SenderThread:44203 [sender.py:send():378] send: run
2024-06-03 12:06:02,263 ERROR   SenderThread:44203 [internal_api.py:execute():344] 404 response executing GraphQL.
2024-06-03 12:06:02,264 ERROR   SenderThread:44203 [internal_api.py:execute():345] {"errors":[{"message":"entity i6 not found during upsertBucket","path":["upsertBucket"]}],"data":{"upsertBucket":null}}
2024-06-03 12:06:02,265 ERROR   SenderThread:44203 [sender.py:send_run():970] It appears that you do not have permission to access the requested resource. Please reach out to the project owner to grant you access. If you have the correct permissions, verify that there are no issues with your networking setup.(Error 404: Not Found)
Traceback (most recent call last):
  File "/Users/rishubbhatia/miniforge3/envs/games/lib/python3.10/site-packages/wandb/sdk/lib/retry.py", line 131, in __call__
    result = self._call_fn(*args, **kwargs)
  File "/Users/rishubbhatia/miniforge3/envs/games/lib/python3.10/site-packages/wandb/sdk/internal/internal_api.py", line 340, in execute
    return self.client.execute(*args, **kwargs)  # type: ignore
  File "/Users/rishubbhatia/miniforge3/envs/games/lib/python3.10/site-packages/wandb/vendor/gql-0.2.0/wandb_gql/client.py", line 52, in execute
    result = self._get_result(document, *args, **kwargs)
  File "/Users/rishubbhatia/miniforge3/envs/games/lib/python3.10/site-packages/wandb/vendor/gql-0.2.0/wandb_gql/client.py", line 60, in _get_result
    return self.transport.execute(document, *args, **kwargs)
  File "/Users/rishubbhatia/miniforge3/envs/games/lib/python3.10/site-packages/wandb/sdk/lib/gql_request.py", line 59, in execute
    request.raise_for_status()
  File "/Users/rishubbhatia/miniforge3/envs/games/lib/python3.10/site-packages/requests/models.py", line 1024, in raise_for_status
    raise HTTPError(http_error_msg, response=self)
requests.exceptions.HTTPError: 404 Client Error: Not Found for url: https://api.wandb.ai/graphql

During handling of the above exception, another exception occurred:

Traceback (most recent call last):
  File "/Users/rishubbhatia/miniforge3/envs/games/lib/python3.10/site-packages/wandb/sdk/internal/sender.py", line 968, in send_run
    server_run = self._init_run(run, config_value_dict)
  File "/Users/rishubbhatia/miniforge3/envs/games/lib/python3.10/site-packages/wandb/sdk/internal/sender.py", line 1013, in _init_run
    server_run, inserted, server_messages = self._api.upsert_run(
  File "/Users/rishubbhatia/miniforge3/envs/games/lib/python3.10/site-packages/wandb/apis/normalize.py", line 73, in wrapper
    raise err
  File "/Users/rishubbhatia/miniforge3/envs/games/lib/python3.10/site-packages/wandb/apis/normalize.py", line 41, in wrapper
    return func(*args, **kwargs)
  File "/Users/rishubbhatia/miniforge3/envs/games/lib/python3.10/site-packages/wandb/sdk/internal/internal_api.py", line 2188, in upsert_run
    response = self.gql(
  File "/Users/rishubbhatia/miniforge3/envs/games/lib/python3.10/site-packages/wandb/sdk/internal/internal_api.py", line 312, in gql
    ret = self._retry_gql(
  File "/Users/rishubbhatia/miniforge3/envs/games/lib/python3.10/site-packages/wandb/sdk/lib/retry.py", line 147, in __call__
    retry_timedelta_triggered = check_retry_fn(e)
  File "/Users/rishubbhatia/miniforge3/envs/games/lib/python3.10/site-packages/wandb/util.py", line 965, in check_retry_fn
    return fallback_retry_fn(e)
  File "/Users/rishubbhatia/miniforge3/envs/games/lib/python3.10/site-packages/wandb/util.py", line 907, in no_retry_auth
    raise CommError(
wandb.errors.CommError: It appears that you do not have permission to access the requested resource. Please reach out to the project owner to grant you access. If you have the correct permissions, verify that there are no issues with your networking setup.(Error 404: Not Found)
2024-06-03 12:06:02,858 DEBUG   HandlerThread:44203 [handler.py:handle_request():158] handle_request: shutdown
2024-06-03 12:06:02,859 INFO    HandlerThread:44203 [handler.py:finish():882] shutting down handler
2024-06-03 12:06:03,282 INFO    SenderThread:44203 [sender.py:finish():1545] shutting down sender
2024-06-03 12:06:03,747 INFO    WriterThread:44203 [datastore.py:close():296] close: /Users/rishubbhatia/Documents/master thesis/Master-Thesis-GNN/wandb/run-20240603_120600-1kln2gg8/run-1kln2gg8.wandb
