2024-07-24 22:05:46,643 INFO    StreamThr :74087 [internal.py:wandb_internal():85] W&B internal server running at pid: 74087, started at: 2024-07-24 22:05:46.639173
2024-07-24 22:05:46,645 DEBUG   HandlerThread:74087 [handler.py:handle_request():158] handle_request: status
2024-07-24 22:05:46,663 INFO    WriterThread:74087 [datastore.py:open_for_write():87] open: /Users/rishubbhatia/Documents/master thesis/Master-Thesis-GNN/wandb/run-20240724_220546-rx5bb5n6/run-rx5bb5n6.wandb
2024-07-24 22:05:46,664 DEBUG   SenderThread:74087 [sender.py:send():378] send: header
2024-07-24 22:05:46,770 DEBUG   SenderThread:74087 [sender.py:send():378] send: run
2024-07-24 22:05:51,795 DEBUG   HandlerThread:74087 [handler.py:handle_request():158] handle_request: keepalive
2024-07-24 22:05:56,824 DEBUG   HandlerThread:74087 [handler.py:handle_request():158] handle_request: keepalive
2024-07-24 22:06:01,850 DEBUG   HandlerThread:74087 [handler.py:handle_request():158] handle_request: keepalive
2024-07-24 22:06:06,886 DEBUG   HandlerThread:74087 [handler.py:handle_request():158] handle_request: keepalive
2024-07-24 22:06:11,902 DEBUG   HandlerThread:74087 [handler.py:handle_request():158] handle_request: keepalive
2024-07-24 22:06:16,926 DEBUG   HandlerThread:74087 [handler.py:handle_request():158] handle_request: keepalive
2024-07-24 22:06:21,953 DEBUG   HandlerThread:74087 [handler.py:handle_request():158] handle_request: keepalive
2024-07-24 22:06:26,973 DEBUG   HandlerThread:74087 [handler.py:handle_request():158] handle_request: keepalive
2024-07-24 22:06:31,993 DEBUG   HandlerThread:74087 [handler.py:handle_request():158] handle_request: keepalive
2024-07-24 22:06:36,786 INFO    SenderThread:74087 [retry.py:__call__():172] Retry attempt failed:
Traceback (most recent call last):
  File "/Users/rishubbhatia/miniforge3/envs/games/lib/python3.10/site-packages/urllib3/connection.py", line 198, in _new_conn
    sock = connection.create_connection(
  File "/Users/rishubbhatia/miniforge3/envs/games/lib/python3.10/site-packages/urllib3/util/connection.py", line 85, in create_connection
    raise err
  File "/Users/rishubbhatia/miniforge3/envs/games/lib/python3.10/site-packages/urllib3/util/connection.py", line 73, in create_connection
    sock.connect(sa)
TimeoutError: [Errno 60] Operation timed out

The above exception was the direct cause of the following exception:

Traceback (most recent call last):
  File "/Users/rishubbhatia/miniforge3/envs/games/lib/python3.10/site-packages/urllib3/connectionpool.py", line 793, in urlopen
    response = self._make_request(
  File "/Users/rishubbhatia/miniforge3/envs/games/lib/python3.10/site-packages/urllib3/connectionpool.py", line 491, in _make_request
    raise new_e
  File "/Users/rishubbhatia/miniforge3/envs/games/lib/python3.10/site-packages/urllib3/connectionpool.py", line 467, in _make_request
    self._validate_conn(conn)
  File "/Users/rishubbhatia/miniforge3/envs/games/lib/python3.10/site-packages/urllib3/connectionpool.py", line 1099, in _validate_conn
    conn.connect()
  File "/Users/rishubbhatia/miniforge3/envs/games/lib/python3.10/site-packages/urllib3/connection.py", line 616, in connect
    self.sock = sock = self._new_conn()
  File "/Users/rishubbhatia/miniforge3/envs/games/lib/python3.10/site-packages/urllib3/connection.py", line 207, in _new_conn
    raise ConnectTimeoutError(
urllib3.exceptions.ConnectTimeoutError: (<urllib3.connection.HTTPSConnection object at 0x117d5f4f0>, 'Connection to api.wandb.ai timed out. (connect timeout=20)')

The above exception was the direct cause of the following exception:

Traceback (most recent call last):
  File "/Users/rishubbhatia/miniforge3/envs/games/lib/python3.10/site-packages/requests/adapters.py", line 589, in send
    resp = conn.urlopen(
  File "/Users/rishubbhatia/miniforge3/envs/games/lib/python3.10/site-packages/urllib3/connectionpool.py", line 847, in urlopen
    retries = retries.increment(
  File "/Users/rishubbhatia/miniforge3/envs/games/lib/python3.10/site-packages/urllib3/util/retry.py", line 515, in increment
    raise MaxRetryError(_pool, url, reason) from reason  # type: ignore[arg-type]
urllib3.exceptions.MaxRetryError: HTTPSConnectionPool(host='api.wandb.ai', port=443): Max retries exceeded with url: /graphql (Caused by ConnectTimeoutError(<urllib3.connection.HTTPSConnection object at 0x117d5f4f0>, 'Connection to api.wandb.ai timed out. (connect timeout=20)'))

During handling of the above exception, another exception occurred:

Traceback (most recent call last):
  File "/Users/rishubbhatia/miniforge3/envs/games/lib/python3.10/site-packages/wandb/sdk/lib/retry.py", line 131, in __call__
    result = self._call_fn(*args, **kwargs)
  File "/Users/rishubbhatia/miniforge3/envs/games/lib/python3.10/site-packages/wandb/sdk/internal/internal_api.py", line 340, in execute
    return self.client.execute(*args, **kwargs)  # type: ignore
  File "/Users/rishubbhatia/miniforge3/envs/games/lib/python3.10/site-packages/wandb/vendor/gql-0.2.0/wandb_gql/client.py", line 52, in execute
    result = self._get_result(document, *args, **kwargs)
  File "/Users/rishubbhatia/miniforge3/envs/games/lib/python3.10/site-packages/wandb/vendor/gql-0.2.0/wandb_gql/client.py", line 60, in _get_result
    return self.transport.execute(document, *args, **kwargs)
  File "/Users/rishubbhatia/miniforge3/envs/games/lib/python3.10/site-packages/wandb/sdk/lib/gql_request.py", line 58, in execute
    request = self.session.post(self.url, **post_args)
  File "/Users/rishubbhatia/miniforge3/envs/games/lib/python3.10/site-packages/requests/sessions.py", line 637, in post
    return self.request("POST", url, data=data, json=json, **kwargs)
  File "/Users/rishubbhatia/miniforge3/envs/games/lib/python3.10/site-packages/requests/sessions.py", line 589, in request
    resp = self.send(prep, **send_kwargs)
  File "/Users/rishubbhatia/miniforge3/envs/games/lib/python3.10/site-packages/requests/sessions.py", line 703, in send
    r = adapter.send(request, **kwargs)
  File "/Users/rishubbhatia/miniforge3/envs/games/lib/python3.10/site-packages/requests/adapters.py", line 610, in send
    raise ConnectTimeout(e, request=request)
requests.exceptions.ConnectTimeout: HTTPSConnectionPool(host='api.wandb.ai', port=443): Max retries exceeded with url: /graphql (Caused by ConnectTimeoutError(<urllib3.connection.HTTPSConnection object at 0x117d5f4f0>, 'Connection to api.wandb.ai timed out. (connect timeout=20)'))
2024-07-24 22:06:37,075 DEBUG   HandlerThread:74087 [handler.py:handle_request():158] handle_request: keepalive
2024-07-24 22:06:42,097 DEBUG   HandlerThread:74087 [handler.py:handle_request():158] handle_request: keepalive
2024-07-24 22:06:47,123 DEBUG   HandlerThread:74087 [handler.py:handle_request():158] handle_request: keepalive
2024-07-24 22:06:52,150 DEBUG   HandlerThread:74087 [handler.py:handle_request():158] handle_request: keepalive
2024-07-24 22:06:57,169 DEBUG   HandlerThread:74087 [handler.py:handle_request():158] handle_request: keepalive
2024-07-24 22:07:02,186 DEBUG   HandlerThread:74087 [handler.py:handle_request():158] handle_request: keepalive
2024-07-24 22:07:07,218 DEBUG   HandlerThread:74087 [handler.py:handle_request():158] handle_request: keepalive
2024-07-24 22:07:12,239 DEBUG   HandlerThread:74087 [handler.py:handle_request():158] handle_request: keepalive
2024-07-24 22:07:17,263 DEBUG   HandlerThread:74087 [handler.py:handle_request():158] handle_request: cancel
2024-07-24 22:07:17,268 DEBUG   SenderThread:74087 [sender.py:send():387] Record cancelled: run
2024-07-24 22:07:17,270 DEBUG   HandlerThread:74087 [handler.py:handle_request():158] handle_request: status_report
2024-07-24 22:07:17,271 DEBUG   HandlerThread:74087 [handler.py:handle_request():158] handle_request: cancel
2024-07-24 22:07:19,462 DEBUG   HandlerThread:74087 [handler.py:handle_request():158] handle_request: shutdown
2024-07-24 22:07:19,463 INFO    HandlerThread:74087 [handler.py:finish():882] shutting down handler
2024-07-24 22:07:20,285 INFO    SenderThread:74087 [sender.py:finish():1545] shutting down sender
2024-07-24 22:07:20,287 INFO    WriterThread:74087 [datastore.py:close():296] close: /Users/rishubbhatia/Documents/master thesis/Master-Thesis-GNN/wandb/run-20240724_220546-rx5bb5n6/run-rx5bb5n6.wandb
